Workbook

Sheet Summary
A1: OrangeHRM 3.3 ESS - My Info Module - Test Summary
A2: All counts are formulas driven by the 'Test Cases' sheet (rows 2-1000), so new cases and status updates are picked up automatically.
A4: Results by Test Type
A5: Test Type | B5: Total | C5: Pass | D5: Fail | E5: Blocked | F5: N/A | G5: Not Run | H5: Execution % | I5: Pass Rate %
A6: Functional | B6: =COUNTIF('Test Cases'!$D$2:$D$1000,$A6) | C6: =COUNTIFS('Test Cases'!$D$2:$D$1000,$A6,'Test Cases'!$N$2:$N$1000,"Pass") | D6: =COUNTIFS('Test Cases'!$D$2:$D$1000,$A6,'Test Cases'!$N$2:$N$1000,"Fail") | E6: =COUNTIFS('Test Cases'!$D$2:$D$1000,$A6,'Test Cases'!$N$2:$N$1000,"Blocked") | F6: =COUNTIFS('Test Cases'!$D$2:$D$1000,$A6,'Test Cases'!$N$2:$N$1000,"N/A") | G6: =COUNTIFS('Test Cases'!$D$2:$D$1000,$A6,'Test Cases'!$N$2:$N$1000,"Not Run") | H6: =IFERROR((C6+D6)/(B6-F6),0) | I6: =IFERROR(C6/(C6+D6),0)
A7: UI | B7: =COUNTIF('Test Cases'!$D$2:$D$1000,$A7) | C7: =COUNTIFS('Test Cases'!$D$2:$D$1000,$A7,'Test Cases'!$N$2:$N$1000,"Pass") | D7: =COUNTIFS('Test Cases'!$D$2:$D$1000,$A7,'Test Cases'!$N$2:$N$1000,"Fail") | E7: =COUNTIFS('Test Cases'!$D$2:$D$1000,$A7,'Test Cases'!$N$2:$N$1000,"Blocked") | F7: =COUNTIFS('Test Cases'!$D$2:$D$1000,$A7,'Test Cases'!$N$2:$N$1000,"N/A") | G7: =COUNTIFS('Test Cases'!$D$2:$D$1000,$A7,'Test Cases'!$N$2:$N$1000,"Not Run") | H7: =IFERROR((C7+D7)/(B7-F7),0) | I7: =IFERROR(C7/(C7+D7),0)
A8: Integration | B8: =COUNTIF('Test Cases'!$D$2:$D$1000,$A8) | C8: =COUNTIFS('Test Cases'!$D$2:$D$1000,$A8,'Test Cases'!$N$2:$N$1000,"Pass") | D8: =COUNTIFS('Test Cases'!$D$2:$D$1000,$A8,'Test Cases'!$N$2:$N$1000,"Fail") | E8: =COUNTIFS('Test Cases'!$D$2:$D$1000,$A8,'Test Cases'!$N$2:$N$1000,"Blocked") | F8: =COUNTIFS('Test Cases'!$D$2:$D$1000,$A8,'Test Cases'!$N$2:$N$1000,"N/A") | G8: =COUNTIFS('Test Cases'!$D$2:$D$1000,$A8,'Test Cases'!$N$2:$N$1000,"Not Run") | H8: =IFERROR((C8+D8)/(B8-F8),0) | I8: =IFERROR(C8/(C8+D8),0)
A9: Security | B9: =COUNTIF('Test Cases'!$D$2:$D$1000,$A9) | C9: =COUNTIFS('Test Cases'!$D$2:$D$1000,$A9,'Test Cases'!$N$2:$N$1000,"Pass") | D9: =COUNTIFS('Test Cases'!$D$2:$D$1000,$A9,'Test Cases'!$N$2:$N$1000,"Fail") | E9: =COUNTIFS('Test Cases'!$D$2:$D$1000,$A9,'Test Cases'!$N$2:$N$1000,"Blocked") | F9: =COUNTIFS('Test Cases'!$D$2:$D$1000,$A9,'Test Cases'!$N$2:$N$1000,"N/A") | G9: =COUNTIFS('Test Cases'!$D$2:$D$1000,$A9,'Test Cases'!$N$2:$N$1000,"Not Run") | H9: =IFERROR((C9+D9)/(B9-F9),0) | I9: =IFERROR(C9/(C9+D9),0)
A10: Compatibility | B10: =COUNTIF('Test Cases'!$D$2:$D$1000,$A10) | C10: =COUNTIFS('Test Cases'!$D$2:$D$1000,$A10,'Test Cases'!$N$2:$N$1000,"Pass") | D10: =COUNTIFS('Test Cases'!$D$2:$D$1000,$A10,'Test Cases'!$N$2:$N$1000,"Fail") | E10: =COUNTIFS('Test Cases'!$D$2:$D$1000,$A10,'Test Cases'!$N$2:$N$1000,"Blocked") | F10: =COUNTIFS('Test Cases'!$D$2:$D$1000,$A10,'Test Cases'!$N$2:$N$1000,"N/A") | G10: =COUNTIFS('Test Cases'!$D$2:$D$1000,$A10,'Test Cases'!$N$2:$N$1000,"Not Run") | H10: =IFERROR((C10+D10)/(B10-F10),0) | I10: =IFERROR(C10/(C10+D10),0)
A11: TOTAL | B11: =SUM(B6:B10) | C11: =SUM(C6:C10) | D11: =SUM(D6:D10) | E11: =SUM(E6:E10) | F11: =SUM(F6:F10) | G11: =SUM(G6:G10) | H11: =IFERROR((C11+D11)/(B11-F11),0) | I11: =IFERROR(C11/(C11+D11),0)
A14: Results by Test Approach
A15: Test Approach | B15: Total | C15: Pass | D15: Fail | E15: Blocked | F15: N/A | G15: Not Run | H15: Execution % | I15: Pass Rate %
A16: Positive | B16: =COUNTIF('Test Cases'!$E$2:$E$1000,$A16) | C16: =COUNTIFS('Test Cases'!$E$2:$E$1000,$A16,'Test Cases'!$N$2:$N$1000,"Pass") | D16: =COUNTIFS('Test Cases'!$E$2:$E$1000,$A16,'Test Cases'!$N$2:$N$1000,"Fail") | E16: =COUNTIFS('Test Cases'!$E$2:$E$1000,$A16,'Test Cases'!$N$2:$N$1000,"Blocked") | F16: =COUNTIFS('Test Cases'!$E$2:$E$1000,$A16,'Test Cases'!$N$2:$N$1000,"N/A") | G16: =COUNTIFS('Test Cases'!$E$2:$E$1000,$A16,'Test Cases'!$N$2:$N$1000,"Not Run") | H16: =IFERROR((C16+D16)/(B16-F16),0) | I16: =IFERROR(C16/(C16+D16),0)
A17: Negative | B17: =COUNTIF('Test Cases'!$E$2:$E$1000,$A17) | C17: =COUNTIFS('Test Cases'!$E$2:$E$1000,$A17,'Test Cases'!$N$2:$N$1000,"Pass") | D17: =COUNTIFS('Test Cases'!$E$2:$E$1000,$A17,'Test Cases'!$N$2:$N$1000,"Fail") | E17: =COUNTIFS('Test Cases'!$E$2:$E$1000,$A17,'Test Cases'!$N$2:$N$1000,"Blocked") | F17: =COUNTIFS('Test Cases'!$E$2:$E$1000,$A17,'Test Cases'!$N$2:$N$1000,"N/A") | G17: =COUNTIFS('Test Cases'!$E$2:$E$1000,$A17,'Test Cases'!$N$2:$N$1000,"Not Run") | H17: =IFERROR((C17+D17)/(B17-F17),0) | I17: =IFERROR(C17/(C17+D17),0)
A18: Boundary | B18: =COUNTIF('Test Cases'!$E$2:$E$1000,$A18) | C18: =COUNTIFS('Test Cases'!$E$2:$E$1000,$A18,'Test Cases'!$N$2:$N$1000,"Pass") | D18: =COUNTIFS('Test Cases'!$E$2:$E$1000,$A18,'Test Cases'!$N$2:$N$1000,"Fail") | E18: =COUNTIFS('Test Cases'!$E$2:$E$1000,$A18,'Test Cases'!$N$2:$N$1000,"Blocked") | F18: =COUNTIFS('Test Cases'!$E$2:$E$1000,$A18,'Test Cases'!$N$2:$N$1000,"N/A") | G18: =COUNTIFS('Test Cases'!$E$2:$E$1000,$A18,'Test Cases'!$N$2:$N$1000,"Not Run") | H18: =IFERROR((C18+D18)/(B18-F18),0) | I18: =IFERROR(C18/(C18+D18),0)
A19: TOTAL | B19: =SUM(B16:B18) | C19: =SUM(C16:C18) | D19: =SUM(D16:D18) | E19: =SUM(E16:E18) | F19: =SUM(F16:F18) | G19: =SUM(G16:G18) | H19: =IFERROR((C19+D19)/(B19-F19),0) | I19: =IFERROR(C19/(C19+D19),0)
A22: Results by Priority
A23: Priority | B23: Total | C23: Pass | D23: Fail | E23: Blocked | F23: N/A | G23: Not Run | H23: Execution % | I23: Pass Rate %
A24: High | B24: =COUNTIF('Test Cases'!$F$2:$F$1000,$A24) | C24: =COUNTIFS('Test Cases'!$F$2:$F$1000,$A24,'Test Cases'!$N$2:$N$1000,"Pass") | D24: =COUNTIFS('Test Cases'!$F$2:$F$1000,$A24,'Test Cases'!$N$2:$N$1000,"Fail") | E24: =COUNTIFS('Test Cases'!$F$2:$F$1000,$A24,'Test Cases'!$N$2:$N$1000,"Blocked") | F24: =COUNTIFS('Test Cases'!$F$2:$F$1000,$A24,'Test Cases'!$N$2:$N$1000,"N/A") | G24: =COUNTIFS('Test Cases'!$F$2:$F$1000,$A24,'Test Cases'!$N$2:$N$1000,"Not Run") | H24: =IFERROR((C24+D24)/(B24-F24),0) | I24: =IFERROR(C24/(C24+D24),0)
A25: Medium | B25: =COUNTIF('Test Cases'!$F$2:$F$1000,$A25) | C25: =COUNTIFS('Test Cases'!$F$2:$F$1000,$A25,'Test Cases'!$N$2:$N$1000,"Pass") | D25: =COUNTIFS('Test Cases'!$F$2:$F$1000,$A25,'Test Cases'!$N$2:$N$1000,"Fail") | E25: =COUNTIFS('Test Cases'!$F$2:$F$1000,$A25,'Test Cases'!$N$2:$N$1000,"Blocked") | F25: =COUNTIFS('Test Cases'!$F$2:$F$1000,$A25,'Test Cases'!$N$2:$N$1000,"N/A") | G25: =COUNTIFS('Test Cases'!$F$2:$F$1000,$A25,'Test Cases'!$N$2:$N$1000,"Not Run") | H25: =IFERROR((C25+D25)/(B25-F25),0) | I25: =IFERROR(C25/(C25+D25),0)
A26: Low | B26: =COUNTIF('Test Cases'!$F$2:$F$1000,$A26) | C26: =COUNTIFS('Test Cases'!$F$2:$F$1000,$A26,'Test Cases'!$N$2:$N$1000,"Pass") | D26: =COUNTIFS('Test Cases'!$F$2:$F$1000,$A26,'Test Cases'!$N$2:$N$1000,"Fail") | E26: =COUNTIFS('Test Cases'!$F$2:$F$1000,$A26,'Test Cases'!$N$2:$N$1000,"Blocked") | F26: =COUNTIFS('Test Cases'!$F$2:$F$1000,$A26,'Test Cases'!$N$2:$N$1000,"N/A") | G26: =COUNTIFS('Test Cases'!$F$2:$F$1000,$A26,'Test Cases'!$N$2:$N$1000,"Not Run") | H26: =IFERROR((C26+D26)/(B26-F26),0) | I26: =IFERROR(C26/(C26+D26),0)
A27: TOTAL | B27: =SUM(B24:B26) | C27: =SUM(C24:C26) | D27: =SUM(D24:D26) | E27: =SUM(E24:E26) | F27: =SUM(F24:F26) | G27: =SUM(G24:G26) | H27: =IFERROR((C27+D27)/(B27-F27),0) | I27: =IFERROR(C27/(C27+D27),0)
A30: Results by 5.9 Check
A31: 5.9 Check | B31: Total | C31: Pass | D31: Fail | E31: Blocked | F31: N/A | G31: Not Run | H31: Execution % | I31: Pass Rate %
A32: Verified | B32: =COUNTIF('Test Cases'!$K$2:$K$1000,$A32) | C32: =COUNTIFS('Test Cases'!$K$2:$K$1000,$A32,'Test Cases'!$N$2:$N$1000,"Pass") | D32: =COUNTIFS('Test Cases'!$K$2:$K$1000,$A32,'Test Cases'!$N$2:$N$1000,"Fail") | E32: =COUNTIFS('Test Cases'!$K$2:$K$1000,$A32,'Test Cases'!$N$2:$N$1000,"Blocked") | F32: =COUNTIFS('Test Cases'!$K$2:$K$1000,$A32,'Test Cases'!$N$2:$N$1000,"N/A") | G32: =COUNTIFS('Test Cases'!$K$2:$K$1000,$A32,'Test Cases'!$N$2:$N$1000,"Not Run") | H32: =IFERROR((C32+D32)/(B32-F32),0) | I32: =IFERROR(C32/(C32+D32),0)
A33: Needs check | B33: =COUNTIF('Test Cases'!$K$2:$K$1000,$A33) | C33: =COUNTIFS('Test Cases'!$K$2:$K$1000,$A33,'Test Cases'!$N$2:$N$1000,"Pass") | D33: =COUNTIFS('Test Cases'!$K$2:$K$1000,$A33,'Test Cases'!$N$2:$N$1000,"Fail") | E33: =COUNTIFS('Test Cases'!$K$2:$K$1000,$A33,'Test Cases'!$N$2:$N$1000,"Blocked") | F33: =COUNTIFS('Test Cases'!$K$2:$K$1000,$A33,'Test Cases'!$N$2:$N$1000,"N/A") | G33: =COUNTIFS('Test Cases'!$K$2:$K$1000,$A33,'Test Cases'!$N$2:$N$1000,"Not Run") | H33: =IFERROR((C33+D33)/(B33-F33),0) | I33: =IFERROR(C33/(C33+D33),0)
A34: N/A on 5.9 | B34: =COUNTIF('Test Cases'!$K$2:$K$1000,$A34) | C34: =COUNTIFS('Test Cases'!$K$2:$K$1000,$A34,'Test Cases'!$N$2:$N$1000,"Pass") | D34: =COUNTIFS('Test Cases'!$K$2:$K$1000,$A34,'Test Cases'!$N$2:$N$1000,"Fail") | E34: =COUNTIFS('Test Cases'!$K$2:$K$1000,$A34,'Test Cases'!$N$2:$N$1000,"Blocked") | F34: =COUNTIFS('Test Cases'!$K$2:$K$1000,$A34,'Test Cases'!$N$2:$N$1000,"N/A") | G34: =COUNTIFS('Test Cases'!$K$2:$K$1000,$A34,'Test Cases'!$N$2:$N$1000,"Not Run") | H34: =IFERROR((C34+D34)/(B34-F34),0) | I34: =IFERROR(C34/(C34+D34),0)
A35: TOTAL | B35: =SUM(B32:B34) | C35: =SUM(C32:C34) | D35: =SUM(D32:D34) | E35: =SUM(E32:E34) | F35: =SUM(F32:F34) | G35: =SUM(G32:G34) | H35: =IFERROR((C35+D35)/(B35-F35),0) | I35: =IFERROR(C35/(C35+D35),0)
A38: Results by Automation
A39: Automation | B39: Total | C39: Pass | D39: Fail | E39: Blocked | F39: N/A | G39: Not Run | H39: Execution % | I39: Pass Rate %
A40: Done | B40: =COUNTIF('Test Cases'!$L$2:$L$1000,$A40) | C40: =COUNTIFS('Test Cases'!$L$2:$L$1000,$A40,'Test Cases'!$N$2:$N$1000,"Pass") | D40: =COUNTIFS('Test Cases'!$L$2:$L$1000,$A40,'Test Cases'!$N$2:$N$1000,"Fail") | E40: =COUNTIFS('Test Cases'!$L$2:$L$1000,$A40,'Test Cases'!$N$2:$N$1000,"Blocked") | F40: =COUNTIFS('Test Cases'!$L$2:$L$1000,$A40,'Test Cases'!$N$2:$N$1000,"N/A") | G40: =COUNTIFS('Test Cases'!$L$2:$L$1000,$A40,'Test Cases'!$N$2:$N$1000,"Not Run") | H40: =IFERROR((C40+D40)/(B40-F40),0) | I40: =IFERROR(C40/(C40+D40),0)
A41: Not yet | B41: =COUNTIF('Test Cases'!$L$2:$L$1000,$A41) | C41: =COUNTIFS('Test Cases'!$L$2:$L$1000,$A41,'Test Cases'!$N$2:$N$1000,"Pass") | D41: =COUNTIFS('Test Cases'!$L$2:$L$1000,$A41,'Test Cases'!$N$2:$N$1000,"Fail") | E41: =COUNTIFS('Test Cases'!$L$2:$L$1000,$A41,'Test Cases'!$N$2:$N$1000,"Blocked") | F41: =COUNTIFS('Test Cases'!$L$2:$L$1000,$A41,'Test Cases'!$N$2:$N$1000,"N/A") | G41: =COUNTIFS('Test Cases'!$L$2:$L$1000,$A41,'Test Cases'!$N$2:$N$1000,"Not Run") | H41: =IFERROR((C41+D41)/(B41-F41),0) | I41: =IFERROR(C41/(C41+D41),0)
A42: TOTAL | B42: =SUM(B40:B41) | C42: =SUM(C40:C41) | D42: =SUM(D40:D41) | E42: =SUM(E40:E41) | F42: =SUM(F40:F41) | G42: =SUM(G40:G41) | H42: =IFERROR((C42+D42)/(B42-F42),0) | I42: =IFERROR(C42/(C42+D42),0)
A45: Results by Section
A46: Section | B46: Total | C46: Pass | D46: Fail | E46: Blocked | F46: N/A | G46: Not Run | H46: Execution % | I46: Pass Rate %
A47: 3.0 Permissions & Access | B47: =COUNTIF('Test Cases'!$B$2:$B$1000,$A47) | C47: =COUNTIFS('Test Cases'!$B$2:$B$1000,$A47,'Test Cases'!$N$2:$N$1000,"Pass") | D47: =COUNTIFS('Test Cases'!$B$2:$B$1000,$A47,'Test Cases'!$N$2:$N$1000,"Fail") | E47: =COUNTIFS('Test Cases'!$B$2:$B$1000,$A47,'Test Cases'!$N$2:$N$1000,"Blocked") | F47: =COUNTIFS('Test Cases'!$B$2:$B$1000,$A47,'Test Cases'!$N$2:$N$1000,"N/A") | G47: =COUNTIFS('Test Cases'!$B$2:$B$1000,$A47,'Test Cases'!$N$2:$N$1000,"Not Run") | H47: =IFERROR((C47+D47)/(B47-F47),0) | I47: =IFERROR(C47/(C47+D47),0)
A48: 3.1 Personal Details | B48: =COUNTIF('Test Cases'!$B$2:$B$1000,$A48) | C48: =COUNTIFS('Test Cases'!$B$2:$B$1000,$A48,'Test Cases'!$N$2:$N$1000,"Pass") | D48: =COUNTIFS('Test Cases'!$B$2:$B$1000,$A48,'Test Cases'!$N$2:$N$1000,"Fail") | E48: =COUNTIFS('Test Cases'!$B$2:$B$1000,$A48,'Test Cases'!$N$2:$N$1000,"Blocked") | F48: =COUNTIFS('Test Cases'!$B$2:$B$1000,$A48,'Test Cases'!$N$2:$N$1000,"N/A") | G48: =COUNTIFS('Test Cases'!$B$2:$B$1000,$A48,'Test Cases'!$N$2:$N$1000,"Not Run") | H48: =IFERROR((C48+D48)/(B48-F48),0) | I48: =IFERROR(C48/(C48+D48),0)
A49: 3.2 Photograph | B49: =COUNTIF('Test Cases'!$B$2:$B$1000,$A49) | C49: =COUNTIFS('Test Cases'!$B$2:$B$1000,$A49,'Test Cases'!$N$2:$N$1000,"Pass") | D49: =COUNTIFS('Test Cases'!$B$2:$B$1000,$A49,'Test Cases'!$N$2:$N$1000,"Fail") | E49: =COUNTIFS('Test Cases'!$B$2:$B$1000,$A49,'Test Cases'!$N$2:$N$1000,"Blocked") | F49: =COUNTIFS('Test Cases'!$B$2:$B$1000,$A49,'Test Cases'!$N$2:$N$1000,"N/A") | G49: =COUNTIFS('Test Cases'!$B$2:$B$1000,$A49,'Test Cases'!$N$2:$N$1000,"Not Run") | H49: =IFERROR((C49+D49)/(B49-F49),0) | I49: =IFERROR(C49/(C49+D49),0)
A50: 3.4 Emergency Contacts | B50: =COUNTIF('Test Cases'!$B$2:$B$1000,$A50) | C50: =COUNTIFS('Test Cases'!$B$2:$B$1000,$A50,'Test Cases'!$N$2:$N$1000,"Pass") | D50: =COUNTIFS('Test Cases'!$B$2:$B$1000,$A50,'Test Cases'!$N$2:$N$1000,"Fail") | E50: =COUNTIFS('Test Cases'!$B$2:$B$1000,$A50,'Test Cases'!$N$2:$N$1000,"Blocked") | F50: =COUNTIFS('Test Cases'!$B$2:$B$1000,$A50,'Test Cases'!$N$2:$N$1000,"N/A") | G50: =COUNTIFS('Test Cases'!$B$2:$B$1000,$A50,'Test Cases'!$N$2:$N$1000,"Not Run") | H50: =IFERROR((C50+D50)/(B50-F50),0) | I50: =IFERROR(C50/(C50+D50),0)
A51: 3.5 Dependents | B51: =COUNTIF('Test Cases'!$B$2:$B$1000,$A51) | C51: =COUNTIFS('Test Cases'!$B$2:$B$1000,$A51,'Test Cases'!$N$2:$N$1000,"Pass") | D51: =COUNTIFS('Test Cases'!$B$2:$B$1000,$A51,'Test Cases'!$N$2:$N$1000,"Fail") | E51: =COUNTIFS('Test Cases'!$B$2:$B$1000,$A51,'Test Cases'!$N$2:$N$1000,"Blocked") | F51: =COUNTIFS('Test Cases'!$B$2:$B$1000,$A51,'Test Cases'!$N$2:$N$1000,"N/A") | G51: =COUNTIFS('Test Cases'!$B$2:$B$1000,$A51,'Test Cases'!$N$2:$N$1000,"Not Run") | H51: =IFERROR((C51+D51)/(B51-F51),0) | I51: =IFERROR(C51/(C51+D51),0)
...

Sheet Test Cases
A1: TC ID | B1: Section | C1: Test Title | D1: Test Type | E1: Test Approach | F1: Priority | G1: Preconditions | H1: Test Data | I1: Steps | J1: Expected Result | K1: 5.9 Check | L1: Automation | M1: Notes | N1: Status | O1: Actual Result
A2: TC-3.0-01 | B2: 3.0 Permissions & Access | C2: My Info menu and all section tabs are displayed | D2: UI | E2: Positive | F2: High | H2: ESS user created by HR Admin | I2: 1. Log in as an ESS user 2. Click My Info 3. Look at the tabs on the left | J2: Ten tabs are shown in this order: Personal Details, Contact Details, Emergency Contacts, Dependents, Immigration, Job, Salary, Report-to, Qualifications, Memberships | K2: Verified | L2: Done | M2: Seen in an ESS screenshot and PASSED in an automated run on the live demo. | N2: Passed
A3: TC-3.0-02 | B3: 3.0 Permissions & Access | C3: Editable sections allow add/edit/delete | D3: Functional | E3: Positive | F3: High | I3: 1. Open Emergency Contacts, Dependents, Immigration, Qualifications and Memberships in turn 2. Check available controls | J3: Add, Edit (via record link) and Delete controls are available in each of these sections, per the ESS permissions | K3: Needs check | L3: Not yet | N3: Not Run
A4: TC-3.0-03 | B4: 3.0 Permissions & Access | C4: Read-only sections expose no modify controls | D4: Functional | E4: Negative | F4: High | I4: 1. Open Job, Report-to (and Salary if visible) 2. Look for Save, Add, Edit and Delete buttons | J4: No Save/Add/Edit/Delete controls are available; all fields are read-only | K4: Needs check | L4: Not yet | M4: 5.x usually asks for confirmation ('Yes, Delete'). Confirm and add it to the steps. | N4: Not Run
A5: TC-3.0-04 | B5: 3.0 Permissions & Access | C5: ESS user cannot open another employee's My Info via URL | D5: Security | E5: Negative | F5: High | H5: Own empNumber +/- 1 | I5: 1. Note the URL of your own My Info page 2. Change the employee number in the URL to another employee's 3. Press Enter | J5: Access is denied or redirected to own record; the other employee's data is never shown | K5: Needs check | L5: Not yet | N5: Not Run
A6: TC-3.0-05 | B6: 3.0 Permissions & Access | C6: ESS changes are visible to HR Admin in PIM | D6: Integration | E6: Positive | F6: Medium | G6: HR Admin account available | I6: 1. As ESS update Nick Name and add an Emergency Contact 2. Log in as HR Admin 3. Open the employee record in PIM | J6: Admin sees the same updated values | K6: Needs check | L6: Not yet | M6: 5.x may hide Nick Name by default (Admin > PIM > Configuration > Optional Fields > deprecated fields). If hidden, mark N/A. | N6: Not Run
A7: TC-3.0-06 | B7: 3.0 Permissions & Access | C7: Training Details permissions | D7: Functional | E7: Positive | F7: Low | I7: 1. Look for a Training Details section in My Info 2. If present, check which fields are editable | J7: If a Training Details section exists: only Feedback is editable; ID, Description, Status and Rating are read-only. If it does not exist, mark N/A on 5.9 | K7: N/A on 5.9 | L7: Not yet | M7: No Training Details tab in the ESS My Info menu (seen on 5.9). | N7: Not Run
A8: TC-3.1-01 | B8: 3.1 Personal Details | C8: Personal Details is the first screen after first login | D8: Functional | E8: Positive | F8: High | G8: Fresh ESS account that has never logged in | I8: 1. Log in for the first time with a new ESS account 2. Observe the landing screen | J8: Personal Details screen (My Info) opens with the user's name and photo in the left panel | K8: Needs check | L8: Not yet | M8: In 5.x login normally lands on the Dashboard, not Personal Details. Expect to rewrite this case. | N8: Not Run
A9: TC-3.1-02 | B9: 3.1 Personal Details | C9: All Personal Details fields and controls are displayed | D9: UI | E9: Positive | F9: Medium | I9: 1. Open Personal Details 2. Check each field and button | J9: Shown: Employee Full Name (First, Middle, Last), Employee Id, Other Id, Driver's License Number, License Expiry Date, Nationality, Marital Status, Date of Birth, Gender (Male/Female), Save button, Custom Fields (Blood Type, Test_Field) with its own Save, Attachments with Add | K9: Needs check | L9: Done | M9: Seen only in a cropped screenshot (no header or side panel), so it may be the Admin view. The ESS screenshot does show the Custom Fields heading. Confirm with the test run or explore-output. | N9: Passed
A10: TC-3.1-03 | B10: 3.1 Personal Details | C10: Required fields are marked with an asterisk | D10: UI | E10: Positive | F10: Low | I10: 1. Open Personal Details 2. Look at the field labels | J10: 'Employee Full Name' is marked with * and the '* Required' note is displayed | K10: Verified | L10: Done | M10: Seen on 5.9 in an ESS screenshot. | N10: Passed
A11: TC-3.1-04 | B11: 3.1 Personal Details | C11: Edit and save Full Name | D11: Functional | E11: Positive | F11: High | H11: James / Robert / Olsen | I11: 1. Change First Name, add Middle Name, change Last Name 2. Click Save (there is no Edit button) 3. Refresh the page | J11: Success message shown; new name is saved and persists after refresh; the name in the left panel is updated | K11: Needs check | L11: Done | M11: 5.x forms are probably editable directly with a Save button (no separate Edit button). Confirm. | N11: Passed
A12: TC-3.1-05 | B12: 3.1 Personal Details | C12: Save with empty First Name | D12: Functional | E12: Negative | F12: High | I12: 1. Clear First Name 2. Click Save | J12: 'Required' error under First Name; nothing is saved | K12: Needs check | L12: Done | N12: Passed
A13: TC-3.1-06 | B13: 3.1 Personal Details | C13: Save with empty Last Name | D13: Functional | E13: Negative | F13: High | I13: 1. Clear Last Name 2. Click Save | J13: 'Required' error under Last Name; nothing is saved | K13: Needs check | L13: Done | N13: Passed
A14: TC-3.1-07 | B14: 3.1 Personal Details | C14: Whitespace-only First Name | D14: Functional | E14: Negative | F14: Medium | H14: ' ' | I14: 1. Replace First Name with spaces only 2. Click Save | J14: Rejected with a 'Required' error | K14: Needs check | L14: Done | N14: Passed
A15: TC-3.1-08 | B15: 3.1 Personal Details | C15: Name length boundary | D15: Functional | E15: Boundary | F15: Medium | H15: Check the field limit in the app (OrangeHRM default is 30) | I15: 1. Enter a name exactly at the maximum length and Save 2. Enter one character more and Save | J15: Maximum-length name is accepted; one character more is rejected with a 'Should not exceed N characters' message | K15: Needs check | L15: Not yet | N15: Not Run
A16: TC-3.1-09 | B16: 3.1 Personal Details | C16: Names with special characters | D16: Functional | E16: Positive | F16: Low | H16: O'Connor / Nancy-Ming | I16: 1. Enter a name containing an apostrophe and a hyphen 2. Click Save | J16: Name is saved and displayed correctly | K16: Needs check | L16: Done | N16: Passed
A17: TC-3.1-10 | B17: 3.1 Personal Details | C17: Edit Other Id | D17: Functional | E17: Positive | F17: Medium | H17: OTH-1001 | I17: 1. Enter a value in Other Id 2. Click Save | J17: Value is saved and persists after refresh | K17: Needs check | L17: Done | N17: Passed
A18: TC-3.1-11 | B18: 3.1 Personal Details | C18: Edit License Expiry Date by typing | D18: Functional | E18: Positive | F18: Medium | H18: Generated valid date in yyyy-dd-mm | I18: 1. Type a valid date in License Expiry Date 2. Click Save | J18: Date is saved in yyyy-dd-mm format | K18: Needs check | L18: Done | M18: Date format follows Admin > Localization in 5.x (default yyyy-mm-dd). Confirm. | N18: Passed
A19: TC-3.1-12 | B19: 3.1 Personal Details | C19: Edit License Expiry Date with the calendar picker | D19: Functional | E19: Positive | F19: Low | I19: 1. Click the calendar icon 2. Pick a date 3. Click Save | J19: Selected date fills the field and is saved | K19: Needs check | L19: Not yet | M19: Date format follows Admin > Localization in 5.x (default yyyy-mm-dd). Confirm. | N19: Not Run
A20: TC-3.1-13 | B20: 3.1 Personal Details | C20: Invalid License Expiry Date format | D20: Functional | E20: Negative | F20: Medium | H20: Generated: dd/mm/yyyy with slashes, yyyy-dd-mm order with day > 12, month 13, day 32, 30 February, letters | I20: 1. Type an invalid date in License Expiry Date 2. Click Save | J20: Validation error 'Should be a valid date in yyyy-dd-mm format'; not saved | K20: Needs check | L20: Done | M20: Date format follows Admin > Localization in 5.x (default yyyy-mm-dd). Confirm. | N20: Passed
A21: TC-3.1-14 | B21: 3.1 Personal Details | C21: Change Gender | D21: Functional | E21: Positive | F21: Medium | I21: 1. Switch Gender from Male to Female 2. Click Save | J21: New gender is saved and persists | K21: Needs check | L21: Done | N21: Passed
A22: TC-3.1-15 | B22: 3.1 Personal Details | C22: Change Nationality | D22: Functional | E22: Positive | F22: Medium | H22: American -> Egyptian | I22: 1. Select another country in Nationality 2. Click Save | J22: Selection is saved and persists | K22: Needs check | L22: Done | N22: Passed
A23: TC-3.1-16 | B23: 3.1 Personal Details | C23: Change Marital Status | D23: Functional | E23: Positive | F23: Medium | H23: Single -> Married | I23: 1. Select another option in Marital Status 2. Click Save | J23: Selection is saved and persists | K23: Needs check | L23: Done | N23: Passed
A24: TC-3.1-17 | B24: 3.1 Personal Details | C24: Edit Nick Name | D24: Functional | E24: Positive | F24: Low | H24: Jimmy -> Jim | I24: 1. Change Nick Name 2. Click Save | J24: Nick name is saved and persists | K24: N/A on 5.9 | L24: Done | M24: Field is not shown to the ESS user on 5.9 (seen in an ESS screenshot); it would appear only if Admin enables optional/deprecated fields. | N24: Not Run
A25: TC-3.1-18 | B25: 3.1 Personal Details | C25: Edit Military Service | D25: Functional | E25: Positive | F25: Low | H25: Army 2005-2008 | I25: 1. Enter text in Military Service 2. Click Save | J25: Value is saved and persists | K25: N/A on 5.9 | L25: Not yet | M25: Field is not shown to the ESS user on 5.9 (seen in an ESS screenshot); it would appear only if Admin enables optional/deprecated fields. | N25: Not Run
A26: TC-3.1-19 | B26: 3.1 Personal Details | C26: Smoker checkbox can be ticked and cleared | D26: Functional | E26: Positive | F26: Low | I26: 1. Tick Smoker and Save 2. Reopen the page 3. Untick Smoker and Save | J26: State follows the selection after each save | K26: N/A on 5.9 | L26: Not yet | M26: Field is not shown to the ESS user on 5.9 (seen in an ESS screenshot); it would appear only if Admin enables optional/deprecated fields. | N26: Not Run
A27: TC-3.1-20 | B27: 3.1 Personal Details | C27: Update several fields in one save | D27: Functional | E27: Positive | F27: Medium | H27: Generated Other Id, Nationality, Marital Status and Gender | I27: 1. Change Other Id, Nationality, Marital Status and Gender together 2. Click Save | J27: All changes are saved together and persist after logout and login | K27: Needs check | L27: Done | N27: Passed
A28: TC-3.1-21 | B28: 3.1 Personal Details | C28: Employee Id is read-only | D28: Functional | E28: Negative | F28: High | I28: 1. Try to click or type in Employee Id | J28: Field is greyed out and cannot be edited | K28: Verified | L28: Done | M28: Greyed out in the ESS screenshot; confirm the disabled attribute when automating. | N28: Passed
A29: TC-3.1-22 | B29: 3.1 Personal Details | C29: Driver's License Number is read-only | D29: Functional | E29: Negative | F29: High | I29: 1. Try to click or type in Driver's License Number | J29: Field is greyed out and cannot be edited | K29: Verified | L29: Done | M29: Greyed out in the ESS screenshot; confirm the disabled attribute when automating. | N29: Passed
A30: TC-3.1-23 | B30: 3.1 Personal Details | C30: Date of Birth is read-only | D30: Functional | E30: Negative | F30: High | I30: 1. Try to type in Date of Birth 2. Click its calendar icon | J30: Field and calendar icon are disabled; value cannot be changed | K30: Verified | L30: Done | M30: Greyed out in the ESS screenshot; confirm the disabled attribute when automating. | N30: Passed
A31: TC-3.1-24 | B31: 3.1 Personal Details | C31: SSN and SIN numbers are read-only (if shown) | D31: Functional | E31: Negative | F31: Medium | I31: 1. Look for SSN Number and SIN Number 2. Try to edit them | J31: Fields are read-only (or not displayed when the optional fields are disabled) | K31: N/A on 5.9 | L31: Not yet | M31: Field is not shown to the ESS user on 5.9 (seen in an ESS screenshot); it would appear only if Admin enables optional/deprecated fields. | N31: Not Run
A32: TC-3.1-25 | B32: 3.1 Personal Details | C32: Read-only fields cannot be changed by tampering with the request | D32: Security | E32: Negative | F32: High | I32: 1. Open browser dev tools and enable the Employee Id / Date of Birth field 2. Change the value 3. Click Save 4. Reload | J32: Server ignores or rejects the change; original values are unchanged | K32: Needs check | L32: Not yet | M32: Date format follows Admin > Localization in 5.x (default yyyy-mm-dd). Confirm. | N32: Not Run
A33: TC-3.1-26 | B33: 3.1 Personal Details | C33: Leave the page without saving | D33: Functional | E33: Positive | F33: Low | I33: 1. Change Nick Name without saving 2. Open another tab in My Info 3. Come back to Personal Details | J33: Unsaved change is not stored; the old value is shown | K33: Needs check | L33: Done | M33: 5.x may hide Nick Name by default (Admin > PIM > Configuration > Optional Fields > deprecated fields). If hidden, mark N/A. | N33: Passed
A34: TC-3.1-27 | B34: 3.1 Personal Details | C34: Personal Details attachments: add and delete | D34: Functional | E34: Positive | F34: Low | H34: Small PDF (under 1MB) | I34: 1. Under Attachments click Add 2. Browse a small file and click Save 3. Tick it and click Delete | J34: File is uploaded, listed, then removed | K34: Needs check | L34: Not yet | M34: 5.x usually asks for confirmation ('Yes, Delete'). Confirm and add it to the steps. | N34: Not Run
A35: TC-3.2-01 | B35: 3.2 Photograph | C35: Open the Photograph page from the profile picture | D35: Functional | E35: Positive | F35: High | I35: 1. Click the photograph at the corner of the screen | J35: Photograph page opens with Choose File, Upload and Delete buttons and the current photo | K35: Needs check | L35: Not yet | M35: 5.x: click the avatar > change profile picture page. Button names (Upload/Save) may differ. The 1MB/jpg/png/gif/200x200 hint IS shown on Add Employee (verified). | N35: Not Run
A36: TC-3.2-02 | B36: 3.2 Photograph | C36: Hint text is displayed | D36: UI | E36: Positive | F36: Low | I36: 1. Open the Photograph page 2. Read the hint under the file field | J36: Hint shows accepted formats (jpg, png, gif), the 1MB limit and recommended size 200px X 200px | K36: Needs check | L36: Not yet | M36: 5.x: click the avatar > change profile picture page. Button names (Upload/Save) may differ. The 1MB/jpg/png/gif/200x200 hint IS shown on Add Employee (verified). The hint text is verified on Add Employee; check the profile picture page too. | N36: Not Run
A37: TC-3.2-03 | B37: 3.2 Photograph | C37: Upload a valid JPG | D37: Functional | E37: Positive | F37: High | H37: Image.jpg, 200x200, about 50 KB | I37: 1. Click Choose File 2. Select a JPG of 1MB or less 3. Click Upload | J37: Success message; new photo is shown in the profile panel | K37: Needs check | L37: Not yet | M37: Check the exact button names and the file-type/size rules on 5.9. | N37: Not Run
A38: TC-3.2-04 | B38: 3.2 Photograph | C38: Upload a valid PNG | D38: Functional | E38: Positive | F38: High | H38: photo.png, 200x200 | I38: 1. Select a PNG of 1MB or less 2. Click Upload | J38: Photo is uploaded and displayed | K38: Needs check | L38: Not yet | M38: Check the exact button names and the file-type/size rules on 5.9. | N38: Not Run
A39: TC-3.2-05 | B39: 3.2 Photograph | C39: Upload a valid GIF | D39: Functional | E39: Positive | F39: Medium | H39: photo.gif, 200x200 | I39: 1. Select a GIF of 1MB or less 2. Click Upload | J39: Photo is uploaded and displayed | K39: Needs check | L39: Not yet | M39: Check the exact button names and the file-type/size rules on 5.9. | N39: Not Run
A40: TC-3.2-06 | B40: 3.2 Photograph | C40: Upload a file of exactly 1MB | D40: Functional | E40: Boundary | F40: Medium | H40: Image of 1,048,576 bytes | I40: 1. Select an image of exactly 1MB (1,048,576 bytes) 2. Click Upload | J40: File is accepted (limit is 'up to 1MB') | K40: Needs check | L40: Not yet | M40: Check the exact button names and the file-type/size rules on 5.9. | N40: Not Run
...

Sheet Notes & Assumptions
A1: HOW TO USE
A2: Filling the sheet | B2: Edit: 5.9 Check and Status (dropdowns), Actual Result, Notes, and Expected Result when 5.9 behaves differently. Unless a Preconditions cell says otherwise, every case starts with the ESS user (created by the setup step, with no data) logged in and the section open. The Automation column is generated from the test code (Done = a test with that TC ID exists).
A3: Status values | B3: Not Run (default), Pass, Fail, Blocked, N/A. Rows get colour automatically.
A5: WHERE THE REQUIREMENTS COME FROM
A6: Source | B6: There is NO official requirements document for OrangeHRM OS 5.9 (the Starter Help Portal only covers Contact Details and Emergency Contacts). These cases were first designed from the OrangeHRM 3.3 ESS guide and are being re-validated section by section on the 5.9 demo.
A7: 5.9 Check column | B7: Verified = behaviour confirmed on the 5.9 demo. Needs check = NOT yet observed on 5.9, so the expected result may change. N/A on 5.9 = the feature does not exist in 5.9 (set after checking).
A8: How to verify a section | B8: 1) Open the section as the ESS user on 5.9. 2) Compare every row of that section. 3) Fix steps/expected results where the app differs. 4) Set 5.9 Check = Verified (or N/A on 5.9). 5) Only then automate it.
A9: Currently verified | B9: Add Employee validations (SETUP); the ESS side panel and the ten My Info tabs; Personal Details layout, read-only fields and no Edit button; date format yyyy-dd-mm (from screenshots). Save/validation behaviour inside My Info becomes Verified when the automated test passes.
A11: HYPOTHESES TO CHECK ON 5.9 (not facts)
A12: Landing page | B12: After login 5.x lands on the Dashboard, not Personal Details (not yet seen).
A13: Salary and Job tabs | B13: Both tabs ARE visible to the ESS user. Check that their content is view-only.
A14: Verified: no Edit button | B14: Personal Details and Contact Details show a Save button directly (ESS screenshots).
A15: Verified: optional fields hidden | B15: Nick Name, Smoker, Military Service and SSN/SIN are NOT shown to the ESS user (ESS screenshot). Custom Fields (Blood Type, Test_Field) are shown instead.
A16: Delete | B16: Delete probably asks for confirmation ('Yes, Delete').
A17: Verified: no Training Details | B17: The ESS My Info menu has no Training Details tab.
A18: Permissions | B18: Which fields/sections an ESS user can edit may be configurable by Admin in 5.x; verify the defaults on the demo.
A20: CLASSIFICATION
A21: Test Type (the goal of the test) | B21: Functional = does the feature behave as expected (add/edit/delete, required fields, validation, read-only fields). UI = what is displayed. Integration = ESS data against another role/module. Security = access control and tampering, only where a restriction is stated. Compatibility = same flow on Chrome, Firefox and Edge.
A22: Test Approach | B22: Positive = valid data / allowed action. Negative = invalid data / forbidden action. Boundary = limits (length, size, dates).
A23: Priority | B23: High = core flow or permission rule (tagged @smoke in code). Medium = important validation or secondary flow. Low = cosmetic or rare edge case.
A25: ENVIRONMENT
A26: Public demo | B26: https://opensource-demo.orangehrmlive.com (OrangeHRM OS 5.9). Users created there disappear after a while, so tests/auth.setup.ts creates a fresh ESS user at the start of every run (TC-SETUP-05). That user has NO data in any section. Do not change the Admin password or touch other people's data.
A27: Test data | B27: Generated at run time by test-data/ (random but valid/invalid on purpose). The seed is printed at the start of each run; SEED=<n> replays the same values. The Test Data column describes the KIND of value; boundary lengths come from test-data/rules.ts (only verified rules).
A28: Date format | B28: yyyy-dd-mm (day before month), taken from the placeholder of the date fields. It is an Admin > Localization setting. Test data uses it (test-data/rules.ts).
A29: Accounts | B29: ESS user = created by the setup step. Admin = the demo's Admin account (setup and SETUP cases only). Cases needing a supervisor / no supervisor / existing data must create that data first (e.g. PIM > Report-to as Admin).
A31: PHASES
A32: Phase 1 - Core (automate first) | B32: Filter Test Type = Functional (and UI), Priority = High first.
A33: Phase 2 - Extended | B33: Integration (Admin context), Security (API level), Compatibility (ALL_BROWSERS=1).
A34: Not covered | B34: Contact Details (not requested yet), Leave/Time/Performance/Directory/Dashboard modules, XSS/injection, session timeout, accessibility, performance, localization.
A36: OPEN QUESTIONS (from the 3.3 guide, re-check on 5.9)
A37: Salary visibility | B37: 3.3 guide said salary is hidden from ESS users but also showed a read-only screen. Decide the 5.9 behaviour and tighten the expected results.
A38: Emergency contact phone | B38: 3.3 guide was inconsistent about whether a phone number is required.
A39: Field length limits | B39: Boundary cases say 'check the limit in the app'. Fill in real values after checking.
A40: Date rules | B40: Whether To/Expiry dates must be after From/Issued dates and whether future birth dates are rejected must be confirmed.
A41: Duplicate rules | B41: Duplicate skill/language handling must be confirmed.
